<?xml version="1.0" ?>
<!-- =================================================================================== -->
<!-- |    This document was autogenerated by xacro from panda_arm.inertial.urdf.xacro  | -->
<!-- |    EDITING THIS FILE BY HAND IS NOT RECOMMENDED                                 | -->
<!-- =================================================================================== -->
<robot name="panda">
  <!-- Link 0 -->
  <link name="panda_link0">
  	<inertial>
      <origin rpy="0 0 0" xyz="-0.0172 0.0004 0.0745"/>
      <mass value="2.3966"/>
      <inertia ixx="0.0090" ixy="0.0000" ixz="0.0020"
          iyy="0.0115" iyz="0.0000" izz="0.0085"/>
    </inertial>
    <collision>
      <origin xyz="0 0 0" rpy="0 0 0"/>
      <geometry>
        <mesh filename="meshes/collision/link0.stl"/>
      </geometry>
    </collision>
    <visual name="fr3_link0_visual">
      <origin xyz="0 0 0" rpy="0 0 0"/>
      <geometry>
        <mesh filename="meshes/visual/link0.dae"/>
      </geometry>
    </visual>
  </link>
  <!-- Link 1 -->
  <link name="panda_link1">
    <inertial>
      <origin xyz="0.0000004128 -0.0181251324 -0.0386035970" rpy="0 0 0"/>
      <mass value="2.9274653454"/>
      <inertia ixx="0.023927316485107913" ixy="1.3317903455714081e-05" ixz="-0.00011404774918616684"
               iyy="0.0224821613275756" iyz="-0.0019950320628240115" izz="0.006350098258530016"/>
    </inertial>
    <collision>
      <origin xyz="0 0 0" rpy="0 0 0"/>
      <geometry>
        <mesh filename="meshes/collision/link1.stl"/>
      </geometry>
    </collision>
    <visual name="fr3_link1_visual">
      <origin xyz="0 0 0" rpy="0 0 0"/>
      <geometry>
        <mesh filename="meshes/visual/link1.dae"/>
      </geometry>
    </visual>
  </link>
  <!-- Joint 1 -->
  <joint name="panda_joint1" type="revolute">
    <safety_controller k_position="100.0" k_velocity="40.0" soft_lower_limit="-2.8973" soft_upper_limit="2.8973"/>
    <origin rpy="0 0 0" xyz="0 0 0.333"/>
    <parent link="panda_link0"/>
    <child link="panda_link1"/>
    <axis xyz="0 0 1"/>
    <limit effort="87.0" lower="-2.7437" upper="2.7437" velocity="2.62"/>
  </joint>
  <!-- Link 2 -->
  <link name="panda_link2">
    <inertial>
      <origin xyz="0.0031828864 -0.0743221644 0.0088146084" rpy="0 0 0"/>
      <mass value="2.9355370338"/>
      <inertia ixx="0.041938946257609425" ixy="0.00020257331521090626" ixz="0.004077784227179924"
               iyy="0.02514514885014724" iyz="-0.0042252158006570156" izz="0.06170214472888839"/>
    </inertial>
    <collision>
      <origin xyz="0 0 0" rpy="0 0 0"/>
      <geometry>
        <mesh filename="meshes/collision/link2.stl"/>
      </geometry>
    </collision>
    <visual name="fr3_link2_visual">
      <origin xyz="0 0 0" rpy="0 0 0"/>
      <geometry>
        <mesh filename="meshes/visual/link2.dae"/>
      </geometry>
    </visual>
  </link>
  <!-- Joint 2 -->
  <joint name="panda_joint2" type="revolute">
    <safety_controller k_position="100.0" k_velocity="40.0" soft_lower_limit="-1.7628" soft_upper_limit="1.7628"/>
    <origin rpy="-1.5688193853667922 0.0005439852849545671 9.75778867075954e-10" xyz="0.00015992930620912919 0.00016537995304946915 -1.612625971446023e-19"/>
    <parent link="panda_link1"/>
    <child link="panda_link2"/>
    <axis xyz="0 0 1"/>
    <limit effort="87.0" lower="-1.7837" upper="1.7837" velocity="2.62"/>
    <dynamics D="1" K="7000" damping="0.003" friction="0.0" mu_coulomb="0" mu_viscous="16"/>
  </joint>
  <!-- Link 3 -->
  <link name="panda_link3">
    <inertial>
      <origin xyz="0.0407015686 -0.0048200565 -0.0289730823" rpy="0 0 0"/>
      <mass value="2.2449013699"/>
      <inertia ixx="0.02410142547240885" ixy="0.002404694559042109" ixz="-0.002856269270114313"
               iyy="0.01974053266708178" iyz="-0.002104212683891874" izz="0.019044494482244823"/>
    </inertial>
    <collision>
      <origin xyz="0 0 0" rpy="0 0 0"/>
      <geometry>
        <mesh filename="meshes/collision/link3.stl"/>
      </geometry>
    </collision>
    <visual name="fr3_link3_visual">
      <origin xyz="0 0 0" rpy="0 0 0"/>
      <geometry>
        <mesh filename="meshes/visual/link3.dae"/>
      </geometry>
    </visual>
  </link>
  <!-- Joint 3 -->
  <joint name="panda_joint3" type="revolute">
    <safety_controller k_position="100.0" k_velocity="40.0" soft_lower_limit="-2.8973" soft_upper_limit="2.8973"/>
    <origin rpy="1.5698897856808722 -0.0022277143821921017 0.0005554730833655623" xyz="-3.631045205078406e-05 -0.316697140343035 0.00016538044311063861"/>
    <parent link="panda_link2"/>
    <child link="panda_link3"/>
    <axis xyz="0 0 1"/>
    <limit effort="87.0" lower="-2.9007" upper="2.9007" velocity="2.62"/>
    <dynamics D="1" K="7000" damping="0.003" friction="0.0" mu_coulomb="0" mu_viscous="16"/>
  </joint>
  <!-- Link 4 -->
  <link name="panda_link4">
    <inertial>
      <origin xyz="-0.0459100965 0.0630492960 -0.0085187868" rpy="0 0 0"/>
      <mass value="2.6155955791"/>
      <inertia ixx="0.03452998321913202" ixy="0.01322552265982813" ixz="0.01015142998484113"
               iyy="0.028881621933049058" iyz="-0.0009762833870704552" izz="0.04125471171146641"/>
    </inertial>
    <collision>
      <geometry>
        <mesh filename="meshes/collision/link4.stl"/>
      </geometry>
    </collision>
    <visual name="fr3_link4_visual">
      <geometry>
        <mesh filename="meshes/visual/link4.dae"/>
      </geometry>
    </visual>
  </link>
  <!-- Joint 4 -->
  <joint name="panda_joint4" type="revolute">
    <safety_controller k_position="100.0" k_velocity="40.0" soft_lower_limit="-3.0718" soft_upper_limit="0.0175"/>
    <origin rpy="1.5692385242654587 0.0008967847005295781 0.0021929508660798376" xyz="0.0822744429253914 0.0004274025276758699 0.0006972686818953394"/>
    <parent link="panda_link3"/>
    <child link="panda_link4"/>
    <axis xyz="0 0 1"/>
    <limit effort="87.0" lower="-3.0421" upper="-0.1518" velocity="2.62"/>
    <dynamics D="1" K="7000" damping="0.003" friction="0.0" mu_coulomb="0" mu_viscous="16"/>
  </joint>
  <!-- Link 5 -->
  <link name="panda_link5">
    <inertial>
      <origin xyz="-0.0016039605 0.0292536262 -0.0972965990" rpy="0 0 0"/>
      <mass value="2.3271207594"/>
      <inertia ixx="0.051610278463662895" ixy="-0.005715173387783472" ixz="-0.0035673167625872135"
               iyy="0.04787729713371481" iyz="0.010673985108535986" izz="0.016423625579357254"/>
    </inertial>
    <collision>
      <geometry>
        <mesh filename="meshes/collision/link5.stl"/>
      </geometry>
      <!-- <material name="panda_white"/> -->
    </collision>
    <visual name="fr3_link5_visual">
      <geometry>
        <mesh filename="meshes/visual/link5.dae"/>
      </geometry>
    </visual>
  </link>
  <!-- Joint 5 -->
  <joint name="panda_joint5" type="revolute">
    <safety_controller k_position="100.0" k_velocity="40.0" soft_lower_limit="-2.8973" soft_upper_limit="2.8973"/>
    <origin rpy="-1.5720416242662738 0.009112100934962829 -0.0006754803382516836" xyz="-0.08209909546126871 0.3847751240945391 -0.0004268082018264021" />
    <parent link="panda_link4"/>
    <child link="panda_link5"/>
    <axis xyz="0 0 1"/>
    <limit effort="12.0" lower="-2.8065" upper="2.8065" velocity="5.26"/>
    <dynamics D="1" K="7000" damping="0.003" friction="0.0" mu_coulomb="0" mu_viscous="16"/>
  </joint>
  <!-- Link 6 -->
  <link name="panda_link6">
    <inertial>
      <origin xyz="0.0597131221 -0.0410294666 -0.0101692726" rpy="0 0 0"/>
      <mass value="1.8170376524"/>
      <inertia ixx="0.005412333594383447" ixy="0.006193456360285834" ixz="0.0014219289306117652"
               iyy="0.014058329545509979" iyz="-0.0013140753741120031" izz="0.016080817924212554"/>
    </inertial>
    <collision>
      <geometry>
        <mesh filename="meshes/collision/link6.stl"/>
      </geometry>
      <!-- <material name="panda_white"/> -->
    </collision>
    <visual name="fr3_link6_visual">
      <geometry>
        <mesh filename="meshes/visual/link6.dae"/>
      </geometry>
    </visual>
  </link>
  <!-- Joint 6 -->
  <joint name="panda_joint6" type="revolute">
    <safety_controller k_position="100.0" k_velocity="40.0" soft_lower_limit="-0.0175" soft_upper_limit="3.7525"/>
    <origin rpy="1.5707145079824067 0.0004267431405131075 0.009112918466830345" xyz="0.0008149146228504592 0.0011270403110451585 0.0007759213813046541" />
    <parent link="panda_link5"/>
    <child link="panda_link6"/>
    <axis xyz="0 0 1"/>
    <limit effort="12.0" lower="0.54092" upper="4.5169" velocity="4.18"/>
    <dynamics D="1" K="7000" damping="0.003" friction="0.0" mu_coulomb="0" mu_viscous="16"/>
  </joint>
  <!-- Link 7 -->
  <link name="panda_link7">
    <inertial>
      <origin xyz="0.0045225817 0.0086261921 -0.0161633251" rpy="0 0 0"/>
      <mass value="0.6271432862"/>
      <inertia ixx="0.00021092389150104718" ixy="-2.433299114461931e-05" ixz="4.564480393778983e-05"
               iyy="0.00017718568002411474" iyz="8.744070223226438e-05" izz="5.993190599659971e-05"/>
    </inertial>
    <collision>
      <geometry>
        <mesh filename="meshes/collision/link7.stl"/>
      </geometry>
    </collision>
    <visual name="fr3_link7_visual">
      <geometry>
        <mesh filename="meshes/visual/link7.dae"/>
      </geometry>
    </visual>
  </link>
  <!-- Joint 7 -->
  <joint name="panda_joint7" type="revolute">
    <safety_controller k_position="100.0" k_velocity="40.0" soft_lower_limit="-2.8973" soft_upper_limit="2.8973"/>
    <origin rpy="1.5710591503330307 1.5080950164913995e-07 -0.00042619955982247103" xyz="0.087001581888464 2.2984836531718647e-06 -0.0011195581933036909" />
    <parent link="panda_link6"/>
    <child link="panda_link7"/>
    <axis xyz="0 0 1"/>
    <limit effort="12.0" lower="-3.0159" upper="3.0159" velocity="5.26"/>
    <dynamics D="1" K="7000" damping="0.003" friction="0.0" mu_coulomb="0" mu_viscous="16"/>
  </joint>
  <!-- Link 8 -->
   <link name="panda_link8" />
  <joint name="panda_joint8" type="fixed">
    <origin rpy="0 0 0" xyz="0 0 0.107" />
    <parent link="panda_link7" />
    <child link="panda_link8" />
  </joint>
  <joint name="panda_hand_joint" type="fixed">
    <parent link="panda_link8" />
    <child link="panda_hand" />
    <origin rpy="0 0 -0.7853981633974483" xyz="0 0 0" />
  </joint>
  <!-- Link hand -->
  <link name="panda_hand">
    <inertial>
      <origin rpy="0 0 0" xyz="-0.0000376 0.0119128 0.0207260"/>
      <mass value="0.6544"/>
      <inertia ixx="0.00186" ixy="0.0" ixz="0.0" iyy="0.0003" iyz="-2e-05" izz="0.00174"/>
    </inertial>
    <collision name="fr3_hand_collision">
      <geometry>
        <mesh filename="meshes/collision/hand.stl"/>
      </geometry>
    </collision>
    <visual>
      <geometry>
        <mesh filename="meshes/visual/hand.dae" />
      </geometry>
    </visual>
  </link>
  <!-- Define the hand_tcp frame -->
  <link name="panda_hand_tcp" />
  <joint name="panda_hand_tcp_joint" type="fixed">
    <origin rpy="0 0 0" xyz="0 0 0.1034" />
    <parent link="panda_hand" />
    <child link="panda_hand_tcp" />
  </joint>
  <!-- Link finger -->
  <link name="panda_leftfinger">
  	<inertial>
      <origin rpy="0 0 0" xyz="0 0.0 0.0"/>
       <mass value="0.015"/>
       <inertia ixx="2.3749999999999997e-06" ixy="0" ixz="0" iyy="2.3749999999999997e-06" iyz="0" izz="7.5e-07"/>
    </inertial>
    <collision>
      <geometry>
        <mesh filename="meshes/collision/finger_soft_l.stl"/>
      </geometry>
    </collision>
    <visual>
      <geometry>
        <mesh filename="meshes/visual/finger_soft_l.dae"/>
      </geometry>
    </visual>
  </link>
  <link name="panda_rightfinger">
  	<inertial>
      <origin rpy="0 0 0" xyz="0 0.0 0.0"/>
       <mass value="0.015"/>
       <inertia ixx="2.3749999999999997e-06" ixy="0" ixz="0" iyy="2.3749999999999997e-06" iyz="0" izz="7.5e-07"/>
    </inertial>
    <collision>
      <geometry>
        <mesh filename="meshes/collision/finger_soft_r.stl"/>
      </geometry>
    </collision>
    <visual>
      <geometry>
        <mesh filename="meshes/visual/finger_soft_r.dae"/>
      </geometry>
    </visual>
  </link>
  <!-- Joint finger -->
  <joint name="panda_finger_joint1" type="prismatic">
    <parent link="panda_hand"/>
    <child link="panda_leftfinger"/>
    <origin rpy="0 0 0" xyz="0 0 0.0584"/>
    <axis xyz="0 1 0"/>
    <limit effort="20" lower="0.0" upper="0.04" velocity="0.2"/>
  </joint>
  <joint name="panda_finger_joint2" type="prismatic">
    <parent link="panda_hand"/>
    <child link="panda_rightfinger"/>
    <origin rpy="0 0 0" xyz="0 0 0.0584"/>
    <axis xyz="0 -1 0"/>
    <limit effort="20" lower="0.0" upper="0.04" velocity="0.2"/>
    <mimic joint="panda_finger_joint1"/>
  </joint>
  </link>


  <!-- MATERIALS -->
  <!-- <material name="panda_white">
    <color rgba="1. 1. 1. 1."/>
  </material>
  <material name="aluminum">
    <color rgba="0.5 0.5 0.5 1"/>
  </material> -->
</robot>
