<?xml version="1.0" ?>
<!-- =================================================================================== -->
<!-- |    This document was autogenerated by xacro from /home/telemaxbase/hector/src/drz_telemax_model/drz_telemax_description/urdf/drz_telemax_complete.urdf.xacro | -->
<!-- |    EDITING THIS FILE BY HAND IS NOT RECOMMENDED                                 | -->
<!-- =================================================================================== -->
<robot name="drz_telemax">
  <!--TODO wenn Kamera auf Handgelenk gesteckt wird, aendern sich die Werte-->
  <material name="Black">
    <color rgba="0.0 0.0 0.0 1.0"/>
  </material>
  <material name="LightBlack">
    <color rgba="0.25 0.25 0.25 1.0"/>
  </material>
  <material name="Blue">
    <color rgba="0.0 0.0 0.8 1.0"/>
  </material>
  <material name="Green">
    <color rgba="0.0 0.8 0.0 1.0"/>
  </material>
  <material name="Gray">
    <color rgba="0.7 0.7 0.7 1.0"/>
  </material>
  <material name="LightGray">
    <color rgba="0.9 0.9 0.9 1.0"/>
  </material>
  <material name="LightGray2">
    <color rgba="0.6 0.6 0.6 1.0"/>
  </material>
  <material name="DarkGray">
    <color rgba="0.5 0.5 0.5 1.0"/>
  </material>
  <material name="DarkGray2">
    <color rgba="0.3 0.3 0.3 1.0"/>
  </material>
  <material name="Red">
    <color rgba="0.8 0.0 0.0 1.0"/>
  </material>
  <material name="White">
    <color rgba="1.0 1.0 1.0 1.0"/>
  </material>
  <material name="Orange">
    <color rgba="1.0 0.5 0.0 1.0"/>
  </material>
  <material name="Front">
    <color rgba="1.0 0.25 0.0 1.0"/>
  </material>
  <material name="Rear">
    <color rgba="0.0 0.5 1.0 1.0"/>
  </material>
  <!-- Measured from CAD file -->
  <!-- Measured from CAD file -->
  <link name="base_link"/>
  <joint name="manipulator_base_joint" type="fixed">
    <origin rpy="0 0 0" xyz="0.225 0.0 0.24125"/>
    <parent link="base_link"/>
    <child link="manipulator_base_link"/>
  </joint>
  <link name="manipulator_base_link">
    <inertial>
      <origin rpy="0 0 0" xyz="0 0 0.0"/>
      <mass value="1"/>
      <inertia ixx="6.666666666666667e-05" ixy="0.0" ixz="0.0" iyy="6.666666666666667e-05" iyz="0.0" izz="6.666666666666667e-05"/>
    </inertial>
<!--    <visual>-->
<!--      <geometry>-->
<!--        <mesh filename="package://drz_telemax_description/meshes/manipulator_base_link.dae" scale="0.001 0.001 0.001"/>-->
<!--      </geometry>-->
<!--    </visual>-->
    <collision>
      <origin rpy="0 0 0" xyz="0.0 0.0 0.0"/>
      <geometry>
        <cylinder length="0.02" radius="0.1"/>
      </geometry>
    </collision>
  </link>
  <joint name="arm_joint_0" type="revolute">
    <parent link="manipulator_base_link"/>
    <child link="arm_link_0"/>
    <origin rpy="0 0 0" xyz="0 0 0"/>
    <axis xyz="0 0 1"/>
    <limit effort="10000.0" lower="-3.6651914291880923" upper="3.6651914291880923" velocity="0.6283185307179586"/>
  </joint>
  <link name="arm_link_0">
    <inertial>
      <origin rpy="0 0 0" xyz="0.00399999999999999 0.021349999999999994 0.126"/>
      <mass value="3"/>
      <inertia ixx="0.0181" ixy="0.0" ixz="0.0" iyy="0.023725" iyz="0.0" izz="0.025625000000000002"/>
    </inertial>
<!--    <visual>-->
<!--      <geometry>-->
<!--        <mesh filename="package://drz_telemax_description/meshes/arm_link_0.dae" scale="0.001 0.001 0.001"/>-->
<!--      </geometry>-->
<!--    </visual>-->
    <!-- Tower body -->
    <collision>
      <origin rpy="0 0 0" xyz="-0.045 0.025 0.16"/>
      <geometry>
        <box size="0.16 0.2 0.18"/>
      </geometry>
    </collision>
    <collision>
      <origin rpy="1.5707963267948966 0 0" xyz="0.055 0.035 0.145"/>
      <geometry>
        <cylinder length="0.17" radius="0.075"/>
      </geometry>
    </collision>
    <collision>
      <origin rpy="0 0.6981317007977318 0" xyz="0.105 0.0 0.205"/>
      <geometry>
        <box size="0.05 0.06 0.02"/>
      </geometry>
    </collision>
    <collision>
      <origin rpy="0 0.6981317007977318 0" xyz="0.045 0.02 0.215"/>
      <geometry>
        <box size="0.05 0.13 0.03"/>
      </geometry>
    </collision>
    <!-- Tower cylinder -->
    <collision>
      <origin rpy="0 0 0" xyz="0.0 0.0 0.03"/>
      <geometry>
        <cylinder length="0.09" radius="0.075"/>
      </geometry>
    </collision>
    <!-- Ring at tower base -->
    <collision>
      <origin rpy="0 0 0" xyz="0.0 0.0 0.0"/>
      <geometry>
        <cylinder length="0.02" radius="0.1"/>
      </geometry>
    </collision>
    <!-- Antenna 1 -->
    <collision>
      <origin rpy="0 0 0" xyz="-0.115 0.09625 0.365"/>
      <geometry>
        <cylinder length="0.22" radius="0.01"/>
      </geometry>
    </collision>
    <!-- Antenna 2 -->
    <collision>
      <origin rpy="0 0 0" xyz="0.015 0.125 0.365"/>
      <geometry>
        <cylinder length="0.22" radius="0.01"/>
      </geometry>
    </collision>
  </link>
  <joint name="arm_joint_1" type="revolute">
    <parent link="arm_link_0"/>
    <child link="arm_link_1"/>
    <origin rpy="0 0 0" xyz="0.06 -0.0815 0.14"/>
    <axis xyz="0 1 0"/>
    <limit effort="10000.0" lower="-2.722713633111154" upper="1.0471975511965976" velocity="0.3141592653589793"/>
  </joint>
  <link name="arm_link_1">
    <!--      <inertial>
        <origin xyz="${-0.066 + (0.066+0.089)/2} 0 0" rpy="0 0 0"/>
        <mass value="1.0" />
        <inertia ixx="1.0" ixy="0.0" ixz="0.0" iyy="1.0" iyz="0.0" izz="1.0" />
      </inertial>-->
    <inertial>
      <origin rpy="0 0 0" xyz="0.33 0 0"/>
      <mass value="5"/>
      <inertia ixx="0.005333333333333333" ixy="0.0" ixz="0.0" iyy="0.26933333333333337" iyz="0.0" izz="0.26933333333333337"/>
    </inertial>
<!--    <visual>-->
<!--      <geometry>-->
<!--        <mesh filename="package://drz_telemax_description/meshes/arm_link_1.dae" scale="0.001 0.001 0.001"/>-->
<!--      </geometry>-->
<!--    </visual>-->
    <collision>
      <origin rpy="0 0 0" xyz="0.01 -0.005 0"/>
      <geometry>
        <box size="0.16 0.08 0.110"/>
      </geometry>
    </collision>
    <collision>
      <origin rpy="0 0 0" xyz="0.26 -0.005 0"/>
      <geometry>
        <box size="0.36 0.08 0.08"/>
      </geometry>
    </collision>
    <collision>
      <origin rpy="0 0 0" xyz="0.56 -0.02 0"/>
      <geometry>
        <box size="0.35 0.085 0.13"/>
      </geometry>
    </collision>
  </link>
  <joint name="arm_joint_2" type="revolute">
    <parent link="arm_link_1"/>
    <child link="arm_link_2"/>
    <origin rpy="0 0 0" xyz="0.67 0.081 0.0"/>
    <axis xyz="0 1 0"/>
    <limit effort="10000.0" lower="-2.9670597283903604" upper="2.9670597283903604" velocity="0.6283185307179586"/>
  </joint>
  <link name="arm_link_2">
    <!--      <inertial>
        <origin xyz="${-0.04 + (0.04+0.04+0.1246)/2} ${0.0634 - (0.0634+0.12-0.08)/2} ${-0.04 + (0.04+0.05)/2}" rpy="0 0 0"/>
        <mass value="1.0" />
        <inertia ixx="1.0" ixy="0.0" ixz="0.0" iyy="1.0" iyz="0.0" izz="1.0" />
      </inertial>-->
    <inertial>
      <origin rpy="0 0 0" xyz="0.01 0.01 0.01"/>
      <mass value="1"/>
      <inertia ixx="0.003508333333333333" ixy="0.0" ixz="0.0" iyy="0.00375" iyz="0.0" izz="0.003508333333333333"/>
    </inertial>
<!--    <visual>-->
<!--      <geometry>-->
<!--        <mesh filename="package://drz_telemax_description/meshes/arm_link_2.dae" scale="0.001 0.001 0.001"/>-->
<!--      </geometry>-->
<!--    </visual>-->
    <collision>
      <origin rpy="0 0 0" xyz="0.01 0.01 0.01"/>
      <geometry>
        <box size="0.15 0.14 0.15"/>
      </geometry>
    </collision>
    <collision>
      <origin rpy="0 0 0" xyz="0.11 0.0 0.0"/>
      <geometry>
        <box size="0.05 0.09 0.09"/>
      </geometry>
    </collision>
  </link>
  <joint name="arm_joint_3" type="revolute">
    <parent link="arm_link_2"/>
    <child link="arm_link_3"/>
    <origin rpy="0 0 0" xyz="0.0 0.0 0.0"/>
    <axis xyz="1 0 0"/>
    <limit effort="10000.0" lower="-3.6651914291880923" upper="3.6651914291880923" velocity="1.2566370614359172"/>
  </joint>
  <link name="arm_link_3">
    <!--      <inertial>
        <origin xyz="${0.494/2} ${0.0523 - 0.1195/2} 0" rpy="0 0 0"/>
        <mass value="1.0" />
        <inertia ixx="1.0" ixy="0.0" ixz="0.0" iyy="1.0" iyz="0.0" izz="1.0" />
      </inertial>-->
    <inertial>
      <origin rpy="0 0 0" xyz="0.3 0.0 0.0"/>
      <mass value="3"/>
      <inertia ixx="0.00405" ixy="0.0" ixz="0.0" iyy="0.05265" iyz="0.0" izz="0.05265"/>
    </inertial>
<!--    <visual>-->
<!--      <geometry>-->
<!--        <mesh filename="package://drz_telemax_description/meshes/arm_link_3.dae" scale="0.001 0.001 0.001"/>-->
<!--      </geometry>-->
<!--    </visual>-->
    <collision>
      <origin rpy="0 0 0" xyz="0.3 0.0 0.0"/>
      <geometry>
        <box size="0.35 0.09 0.09"/>
      </geometry>
    </collision>
    <collision>
      <origin rpy="0 0 0" xyz="0.53 0.055 0"/>
      <geometry>
        <box size="0.25 0.045 0.09"/>
      </geometry>
    </collision>
    <collision>
      <origin rpy="0 0 0" xyz="0.46 0.01 0"/>
      <geometry>
        <box size="0.13 0.13 0.09"/>
      </geometry>
    </collision>
  </link>
  <joint name="arm_joint_4" type="revolute">
    <parent link="arm_link_3"/>
    <child link="arm_link_4"/>
    <origin rpy="0 0 0" xyz="0.615 0.0 0.0"/>
    <axis xyz="0 1 0"/>
    <limit effort="10000.0" lower="-2.2689280275926285" upper="2.2689280275926285" velocity="1.361356816555577"/>
  </joint>
  <link name="arm_link_4">
    <!--      <inertial>
        <origin xyz="${-0.059 + 0.168/2} ${-0.046 + 0.076/2.0} ${-0.0367 + (0.0513+0.0367)/2}" rpy="0 0 0"/>
        <mass value="1.0" />
        <inertia ixx="1.0" ixy="0.0" ixz="0.0" iyy="1.0" iyz="0.0" izz="1.0" />
      </inertial>-->
    <inertial>
      <origin rpy="0 0 0" xyz="0.025 -0.01 0.005"/>
      <mass value="1"/>
      <inertia ixx="0.0015083333333333333" ixy="0.0" ixz="0.0" iyy="0.00435" iyz="0.0" izz="0.004508333333333333"/>
    </inertial>
<!--    <visual>-->
<!--      <geometry>-->
<!--        <mesh filename="package://drz_telemax_description/meshes/arm_link_4.dae" scale="0.001 0.001 0.001"/>-->
<!--      </geometry>-->
<!--    </visual>-->
    <collision>
      <origin rpy="0 0 0" xyz="0.025 -0.01 0.005"/>
      <geometry>
        <box size="0.21 0.1 0.09"/>
      </geometry>
    </collision>
    <collision>
      <origin rpy="0 0 0" xyz="0.0625 -0.00125 0.055"/>
      <geometry>
        <cylinder length="0.02" radius="0.03"/>
      </geometry>
    </collision>
  </link>
  <joint name="arm_joint_5" type="continuous">
    <parent link="arm_link_4"/>
    <child link="arm_link_5"/>
    <origin rpy="3.141592653589793 0 0" xyz="0.12887 0.0 0.00065"/>
    <axis xyz="1 0 0"/>
    <limit effort="10000.0" velocity="1.2915436464758039"/>
  </joint>
  <link name="arm_link_5">
    <!--      <inertial>
        <origin xyz="${0.063/2} 0 ${-0.0525 + (0.0184+0.0525)/2}" rpy="0 0 0"/>
        <mass value="1.0" />
        <inertia ixx="1.0" ixy="0.0" ixz="0.0" iyy="1.0" iyz="0.0" izz="1.0" />
      </inertial>-->
    <inertial>
      <origin rpy="0 0 0" xyz="0.036 0.0 0.0"/>
      <mass value="0.5"/>
      <inertia ixx="0.0009010416666666667" ixy="0.0" ixz="0.0" iyy="0.00031874999999999997" iyz="0.0" izz="0.0010510416666666667"/>
    </inertial>
<!--    <visual>-->
<!--      <geometry>-->
<!--        <mesh filename="package://drz_telemax_description/meshes/arm_link_5.dae" scale="0.001 0.001 0.001"/>-->
<!--      </geometry>-->
<!--    </visual>-->
    <collision>
      <origin rpy="0 0 0" xyz="0.036 0.0 0.0"/>
      <geometry>
        <box size="0.075 0.14 0.045"/>
      </geometry>
    </collision>
    <collision>
      <origin rpy="0 0 0" xyz="0.03 0.0 0.035"/>
      <geometry>
        <box size="0.045 0.045 0.045"/>
      </geometry>
    </collision>
  </link>
</robot>


